<?xml version="1.0"?>

<robot name="gofa_arm_urdf">


    <!-- World Definition -->
    <link name="world"/>


    <!-- Links Definition -->
    <!-- BASE LINK -->
    <link name="base_link">
        <visual>
            <geometry>
                <mesh filename="package://pastabot_pkg/mesh/GoFa_Base.stl" scale="0.001 0.001 0.001"/>
            </geometry>
            <origin xyz="0.0 0.0 0.0" rpy="0.0 0.0 0.0"/>
        </visual>
        <collision>
            <geometry>
                <mesh filename="package://pastabot_pkg/mesh/GoFa_Base.stl" scale="0.001 0.001 0.001"/>
            </geometry>
        </collision>
        <inertial>
            <mass value="10"/>
            <inertia ixx="0.4" ixy="0.0" ixz="0.0" iyy="0.4" iyz="0.0" izz="0.2"/>
            <origin xyz="0 0 0" rpy="0 0 0"/>
        </inertial>
    </link>
    <gazebo reference="base_link">
        <material>Gazebo/Yellow</material>
        <plugin name="gazebo_ros_control" filename="libgazebo_ros_control.so">
            <robotNamespace>/</robotNamespace>
        </plugin>
    </gazebo>

    <!-- LINK01 Revolutional - Visualization and Physics -->
    <link name="link01_rev1">
        <visual>
            <geometry>
                <mesh filename="package://pastabot_pkg/mesh/GoFa_Link1.stl" scale="0.001 0.001 0.001"/>
            </geometry>
            <origin xyz="0.0 0.0 0.0" rpy="0.0 0.0 0.0"/>
        </visual>
        <collision>
            <geometry>
                <mesh filename="package://pastabot_pkg/mesh/GoFa_Link1.stl" scale="0.001 0.001 0.001"/>
            </geometry>
            <origin xyz="0.0 0.0 0.0" rpy="0.0 0.0 0.0"/>
        </collision>
        <inertial>
            <mass value="0.1"/>
            <origin xyz="0 0 0" rpy="0 0 0"/>
            <inertia ixx="0.03" iyy="0.03" izz="0.03" ixy="0.0" ixz="0.0" iyz="0.0"/>
        </inertial>
    </link>
    <gazebo reference="link01_rev1">
        <material>Gazebo/Yellow</material>
    </gazebo>

    <!-- LINK01 DH - Modeling Cinematic Transformations -->
    <link name="link01_DH">
        <inertial>
            <mass value="1"/>
            <inertia ixx="0.4" ixy="0.0" ixz="0.0" iyy="0.4" iyz="0.0" izz="0.2"/>
        </inertial>
    </link>

    <!-- LINK02 Revolutional - Visualization and Physics -->
    <link name="link02_rev2">
        <visual>
            <geometry>
                <mesh filename="package://pastabot_pkg/mesh/GoFa_Link2.stl" scale="0.001 0.001 0.001"/>
            </geometry>
            <origin xyz="0.0 0.265 0.0" rpy="1.570795 0.0 0.0"/>
        </visual>
        <collision>
            <geometry>
                <mesh filename="package://pastabot_pkg/mesh/GoFa_Link2.stl" scale="0.001 0.001 0.001"/>
            </geometry>
            <origin xyz="0.0 0.265 0.0" rpy="1.570795 0.0 0.0"/>
        </collision>
        <inertial>
            <mass value="0.1"/>
            <origin xyz="0 0 0" rpy="0 0 0"/>
            <inertia ixx="0.03" iyy="0.03" izz="0.03" ixy="0.0" ixz="0.0" iyz="0.0"/>
        </inertial>
    </link>
    <gazebo reference="link02_rev2">
        <material>Gazebo/Yellow</material>
    </gazebo>

    <!-- LINK02 DH - Modeling Cinematic Transformations -->
    <link name="link02_DH">
        <inertial>
            <mass value="1"/>
            <inertia ixx="0.4" ixy="0.0" ixz="0.0" iyy="0.4" iyz="0.0" izz="0.2"/>
        </inertial>
    </link>

    <!-- LINK03 Revolutional - Visualization and Physics -->
    <link name="link03_rev3">
        <visual>
            <geometry>
                <mesh filename="package://pastabot_pkg/mesh/GoFa_Link3.stl" scale="0.001 0.001 0.001"/>
            </geometry>
            <origin xyz="-0.709 0.0 0.0 " rpy="1.570795 0.0 1.570795"/>
        </visual>
        <collision>
            <geometry>
                <mesh filename="package://pastabot_pkg/mesh/GoFa_Link3.stl" scale="0.001 0.001 0.001"/>
            </geometry>
            <origin xyz="-0.709 0.0 0.0 " rpy="1.570795 0.0 1.570795"/>
        </collision>
        <inertial>
            <mass value="0.1"/>
            <origin xyz="0 0 0" rpy="0 0 0"/>
            <inertia ixx="0.03" iyy="0.03" izz="0.03" ixy="0.0" ixz="0.0" iyz="0.0"/>
        </inertial>
    </link>
    <gazebo reference="link03_rev3">
        <material>Gazebo/Yellow</material>
    </gazebo>

    <!-- LINK03 DH - Modeling Cinematic Transformations -->
    <link name="link03_DH">
        <inertial>
            <mass value="1"/>
            <inertia ixx="0.4" ixy="0.0" ixz="0.0" iyy="0.4" iyz="0.0" izz="0.2"/>
        </inertial>
    </link>

    <!-- LINK04 Revolutional - Visualization and Physics -->
    <link name="link04_rev4">
        <visual>
            <geometry>
                <mesh filename="package://pastabot_pkg/mesh/GoFa_Link4.stl" scale="0.001 0.001 0.001"/>
            </geometry>
            <origin xyz="-0.819 0.0 0.0" rpy="3.14159 -1.570795 0.0"/>
        </visual>
        <collision>
            <geometry>
                <mesh filename="package://pastabot_pkg/mesh/GoFa_Link4.stl" scale="0.001 0.001 0.001"/>
            </geometry>
            <origin xyz="-0.819 0.0 0.0" rpy="3.14159 -1.570795 0.0"/>
        </collision>
        <inertial>
            <mass value="0.1"/>
            <origin xyz="0 0 0" rpy="0 0 0"/>
            <inertia ixx="0.03" iyy="0.03" izz="0.03" ixy="0.0" ixz="0.0" iyz="0.0"/>
        </inertial>
    </link>
    <gazebo reference="link04_rev4">
        <material>Gazebo/Yellow</material>
    </gazebo>

    <!-- LINK04 DH - Modeling Cinematic Transformations -->
    <link name="link04_DH">
        <inertial>
            <mass value="1"/>
            <inertia ixx="0.4" ixy="0.0" ixz="0.0" iyy="0.4" iyz="0.0" izz="0.2"/>
        </inertial>
    </link>

    <!-- LINK05 Revolutional - Visualization and Physics -->
    <link name="link05_rev5">
        <visual>
            <geometry>
                <mesh filename="package://pastabot_pkg/mesh/GoFa_Link5.stl" scale="0.001 0.001 0.001"/>
            </geometry>
            <origin xyz="-0.819 -0.47 0.0" rpy="1.570795 0.0 1.570795"/>
        </visual>
        <collision>
            <geometry>
                <mesh filename="package://pastabot_pkg/mesh/GoFa_Link5.stl" scale="0.001 0.001 0.001"/>
            </geometry>
            <origin xyz="-0.819 -0.47 0.0" rpy="1.570795 0.0 1.570795"/>
        </collision>
        <inertial>
            <mass value="0.1"/>
            <origin xyz="0 0 0" rpy="0 0 0"/>
            <inertia ixx="0.03" iyy="0.03" izz="0.03" ixy="0.0" ixz="0.0" iyz="0.0"/>
        </inertial>
    </link>
    <gazebo reference="link05_rev5">
        <material>Gazebo/Yellow</material>
    </gazebo>

    <!-- LINK05 DH - Modeling Cinematic Transformations -->
    <link name="link05_DH">
        <inertial>
            <mass value="1"/>
            <inertia ixx="0.4" ixy="0.0" ixz="0.0" iyy="0.4" iyz="0.0" izz="0.2"/>
        </inertial>
    </link>

    <!-- LINK06 Revolutional - Visualization and Physics -->
    <link name="link06_rev6">
        <visual>
            <geometry>
                <mesh filename="package://pastabot_pkg/mesh/GoFa_Link6.stl" scale="0.001 0.001 0.001"/>
            </geometry>
            <origin xyz="-0.899 0.0 -0.47" rpy="0.0 -1.570795 3.14159"/>
        </visual>
        <collision>
            <geometry>
                <mesh filename="package://pastabot_pkg/mesh/GoFa_Link6.stl" scale="0.001 0.001 0.001"/>
            </geometry>
            <origin xyz="-0.899 0.0 -0.47" rpy="0.0 -1.570795 3.14159"/>
            <material name="green"/>
        </collision>
        <inertial>
            <mass value="0.1"/>
            <origin xyz="0 0 0" rpy="0 0 0"/>
            <inertia ixx="0.03" iyy="0.03" izz="0.03" ixy="0.0" ixz="0.0" iyz="0.0"/>
        </inertial>
        <gazebo>
            <sensor type="force_torque" name="ft_sensor">
                <always_on>true</always_on>
                <update_rate>100.0</update_rate>
                <force_torque>
                    <frame>child</frame>
                    <measure_direction>child_to_parent</measure_direction>
                </force_torque>
            </sensor>
        </gazebo>
    </link>
    <gazebo reference="link06_rev6">
        <material>Gazebo/Yellow</material>
    </gazebo>

    <!-- LINK06 DH - Modeling Cinematic Transformations -->
    <link name="link06_DH">
        <inertial>
            <mass value="1"/>
            <inertia ixx="0.4" ixy="0.0" ixz="0.0" iyy="0.4" iyz="0.0" izz="0.2"/>
        </inertial>
    </link>

    <!-- GRIPPER LINK -->
    <link name="gripper_fixed">
        <visual>
            <geometry>
                <mesh filename="package://pastabot_pkg/mesh/SR24_02_ExeAHTool.stl" scale="0.001 0.001 0.001"/>
            </geometry>
            <origin xyz="0 0.0 -0.150" rpy="0.0 0 0"/>
        </visual>
        <collision>
            <geometry>
                <mesh filename="package://pastabot_pkg/mesh/SR24_02_ExeAHTool.stl" scale="0.001 0.001 0.001"/>
            </geometry>
            <origin xyz="0 0.0 -0.150" rpy="0.0 0 0"/>
        </collision>
        <inertial>
            <mass value="1"/>
            <inertia ixx="0.4" ixy="0.0" ixz="0.0" iyy="0.4" iyz="0.0" izz="0.2"/>
            <origin xyz="0 0 0" rpy="0 0 0"/>
        </inertial>
    </link>
    <gazebo reference="gripper_fixed">
        <material>Gazebo/Yellow</material>
    </gazebo>


    <!-- Joints Definition -->
    <!-- BASE JOINT (fixed) -->
    <joint name="fixed" type="fixed">
        <parent link="world"/>
        <child link="base_link"/>
    </joint>

    <!-- JOINT1 Revolutional -->
    <joint name="jnt1_rev" type="revolute">
        <parent link="base_link"/>
        <child link="link01_rev1"/>
        <axis xyz="0 0 1"/>
        <limit lower="-3.14159" upper="3.14159" velocity="50.0" effort="1000.0"/>
        <origin xyz="0 0 0" rpy="0 0 0"/>
        <dynamics damping="0.5" friction="0.5"/>
    </joint>

    <!-- JOINT1 DH -->
    <joint name="jnt1_DH" type="fixed">
        <parent link="link01_rev1"/>
        <child link="link01_DH"/>
        <origin xyz="0 0 0.265" rpy="-1.570795 0 0"/>
    </joint>

    <!-- JOINT2 Revolutional -->
    <joint name="jnt2_rev" type="revolute">
        <parent link="link01_DH"/>
        <child link="link02_rev2"/>
        <axis xyz="0 0 1"/>
        <limit lower="-1.5708" upper="1.5708" velocity="50.0" effort="1000.0"/>
        <origin xyz="0 0 0" rpy="0 0 0"/>
        <dynamics damping="0.5" friction="0.5"/>
    </joint>

    <!-- JOINT2 DH -->
    <joint name="jnt2_DH" type="fixed">
        <parent link="link02_rev2"/>
        <child link="link02_DH"/>
        <limit lower="-1.5708" upper="1.5708" velocity="50.0" effort="1000.0"/>
        <origin xyz="0 -0.444 0" rpy="0 0 -1.570795"/>
    </joint>

    <!-- JOINT3 Revolutional -->
    <joint name="jnt3_rev" type="revolute">
        <parent link="link02_DH"/>
        <child link="link03_rev3"/>
        <axis xyz="0 0 1"/>
        <limit lower="-1.5708" upper="1.5708" velocity="50.0" effort="1000.0"/>
        <origin xyz="0 0 0" rpy="0 0 0"/>
        <dynamics damping="0.5" friction="0.5"/>
    </joint>

    <!-- JOINT3 DH -->
    <joint name="jnt3_DH" type="fixed">
        <parent link="link03_rev3"/>
        <child link="link03_DH"/>
        <limit lower="-1.5708" upper="1.5708" velocity="50.0" effort="1000.0"/>
        <origin xyz="0.11 0 0" rpy="-1.570795 0 0"/>
    </joint>

    <!-- JOINT4 Revolutional -->
    <joint name="jnt4_rev" type="revolute">
        <parent link="link03_DH"/>
        <child link="link04_rev4"/>
        <axis xyz="0 0 1"/>
        <limit lower="-3.14159" upper="3.14159" velocity="50.0" effort="1000.0"/>
        <origin xyz="0 0 0" rpy="0 0 0"/>
        <dynamics damping="0.5" friction="0.5"/>
    </joint>

    <!-- JOINT4 DH -->
    <joint name="jnt4_DH" type="fixed">
        <parent link="link04_rev4"/>
        <child link="link04_DH"/>
        <limit lower="-3.14159" upper="3.14159" velocity="50.0" effort="1000.0"/>
        <origin xyz="0 0 0.47" rpy="1.570795 0 0"/>
    </joint>

    <!-- JOINT5 Revolutional -->
    <joint name="jnt5_rev" type="revolute">
        <parent link="link04_DH"/>
        <child link="link05_rev5"/>
        <axis xyz="0 0 1"/>
        <limit lower="-3.14159" upper="3.14159" velocity="50.0" effort="1000.0"/>
        <origin xyz="0 0 0" rpy="0 0 0"/>
        <dynamics damping="0.5" friction="0.5"/>
    </joint>

    <!-- JOINT5 DH -->
    <joint name="jnt5_DH" type="fixed">
        <parent link="link05_rev5"/>
        <child link="link05_DH"/>
        <limit lower="-3.14159" upper="3.14159" velocity="50.0" effort="1000.0"/>
        <origin xyz="0.08 0 0" rpy="-1.570795 0 0"/>
    </joint>

    <!-- JOINT6 Revolutional -->
    <joint name="jnt6_rev" type="revolute">
        <parent link="link05_DH"/>
        <child link="link06_rev6"/>
        <axis xyz="0 0 1"/>
        <limit lower="-3.14159" upper="3.14159" velocity="50.0" effort="1000.0"/>
        <origin xyz="0 0 0" rpy="0 0 0"/>
        <dynamics damping="0.5" friction="0.5"/>
    </joint>
    <gazebo reference="jnt6_rev">
        <provideFeedback>true</provideFeedback>  <!-- Enable Joint Feedback for End Effector Joint -->
    </gazebo>

    <!-- JOINT6 DH -->
    <joint name="jnt6_DH" type="fixed">
        <parent link="link06_rev6"/>
        <child link="link06_DH"/>
        <limit lower="-3.14159" upper="3.14159" velocity="50.0" effort="1000.0"/>
        <origin xyz="0 0 0.101" rpy="0 0 3.14159"/>
    </joint>

    <!-- JOINT GRIPPER DH -->
    <joint name="jnt_gripper" type="fixed">
        <parent link="link06_DH"/>
        <child link="gripper_fixed"/>
        <limit lower="-3.14159" upper="3.14159" velocity="50.0" effort="1000.0"/>
        <origin xyz="0 0 0.150" rpy="0 0 0"/>
    </joint>


    <!-- Transmissions Definition -->
    <!-- JOINT1 -->
    <transmission name="jnt1_rev_simple_trans">
        <type>transmission_interface/SimpleTransmission</type>
        <joint name="jnt1_rev">
            <hardwareInterface>hardware_interface/PositionJointInterface</hardwareInterface>
        </joint>
        <actuator name="jnt1_rev_motor">
            <mechanicalReduction>1</mechanicalReduction>
            <hardwareInterface>hardware_interface/PositionJointInterface</hardwareInterface>
        </actuator>
    </transmission>

    <!-- JOINT2 -->
    <transmission name="jnt2_rev_simple_trans">
        <type>transmission_interface/SimpleTransmission</type>
        <joint name="jnt2_rev">
            <hardwareInterface>hardware_interface/PositionJointInterface</hardwareInterface>
        </joint>
        <actuator name="jnt2_rev_motor">
            <mechanicalReduction>1</mechanicalReduction>
            <hardwareInterface>hardware_interface/PositionJointInterface</hardwareInterface>
        </actuator>
    </transmission>

    <!-- JOINT3 -->
    <transmission name="jnt3_rev_simple_trans">
        <type>transmission_interface/SimpleTransmission</type>
        <joint name="jnt3_rev">
            <hardwareInterface>hardware_interface/PositionJointInterface</hardwareInterface>
        </joint>
        <actuator name="jnt3_rev_motor">
            <mechanicalReduction>1</mechanicalReduction>
            <hardwareInterface>hardware_interface/PositionJointInterface</hardwareInterface>
        </actuator>
    </transmission>

    <!-- JOINT4 -->
    <transmission name="jnt4_rev_simple_trans">
        <type>transmission_interface/SimpleTransmission</type>
        <joint name="jnt4_rev">
            <hardwareInterface>hardware_interface/PositionJointInterface</hardwareInterface>
        </joint>
        <actuator name="jnt4_rev_motor">
            <mechanicalReduction>1</mechanicalReduction>
            <hardwareInterface>hardware_interface/PositionJointInterface</hardwareInterface>
        </actuator>
    </transmission>

    <!-- JOINT5 -->
    <transmission name="jnt5_rev_simple_trans">
        <type>transmission_interface/SimpleTransmission</type>
        <joint name="jnt5_rev">
            <hardwareInterface>hardware_interface/PositionJointInterface</hardwareInterface>
        </joint>
        <actuator name="jnt5_rev_motor">
            <mechanicalReduction>1</mechanicalReduction>
            <hardwareInterface>hardware_interface/PositionJointInterface</hardwareInterface>
        </actuator>
    </transmission>

    <!-- JOINT6 -->
    <transmission name="jnt6_rev_simple_trans">
        <type>transmission_interface/SimpleTransmission</type>
        <joint name="jnt6_rev">
            <hardwareInterface>hardware_interface/PositionJointInterface</hardwareInterface>
        </joint>
        <actuator name="jnt6_rev_motor">
            <mechanicalReduction>1</mechanicalReduction>
            <hardwareInterface>hardware_interface/PositionJointInterface</hardwareInterface>
        </actuator>
    </transmission>


    <!-- Gazebo -->
    <gazebo>
        <!-- Control Plugin -->
        <plugin name="control" filename="libgazebo_ros_control.so">
            <robotNamespace>/</robotNamespace>
            <controlPeriod>0.001</controlPeriod>
            <robotParam>/robot_description</robotParam>
        </plugin>

        <!-- Force Sensor Plugin -->
        <plugin name="ft_sensor" filename="libgazebo_ros_ft_sensor.so">
            <updateRate>100.0</updateRate>
            <topicName>ft_sensor_topic</topicName>
            <jointName>jnt6_rev</jointName>
        </plugin>
    </gazebo>

</robot>